telegram.ext.updater - INFO - Received signal 2 (SIGINT), stopping...
telegram.ext.updater - WARNING - Exiting immediately!
telegram.ext.updater - INFO - Received signal 2 (SIGINT), stopping...
telegram.ext.updater - WARNING - Exiting immediately!
telegram.ext.updater - INFO - Received signal 2 (SIGINT), stopping...
telegram.ext.updater - WARNING - Exiting immediately!
telegram.ext.updater - INFO - Received signal 2 (SIGINT), stopping...
telegram.ext.updater - WARNING - Exiting immediately!
telegram.ext.updater - INFO - Received signal 2 (SIGINT), stopping...
telegram.ext.updater - WARNING - Exiting immediately!
telegram.ext.dispatcher - ERROR - An uncaught error was raised while processing the update
Traceback (most recent call last):
  File "/Users/irina/Documents/Projects/Lesson3/env/lib/python3.6/site-packages/telegram/ext/dispatcher.py", line 279, in process_update
    handler.handle_update(update, self)
  File "/Users/irina/Documents/Projects/Lesson3/env/lib/python3.6/site-packages/telegram/ext/commandhandler.py", line 173, in handle_update
    return self.callback(dispatcher.bot, update, **optional_args)
  File "bot.py", line 28, in find_planet
    mars = ephem.Mars(datetime.datetime.now)
NameError: name 'datetime' is not defined
telegram.ext.dispatcher - ERROR - An uncaught error was raised while processing the update
Traceback (most recent call last):
  File "/Users/irina/Documents/Projects/Lesson3/env/lib/python3.6/site-packages/telegram/ext/dispatcher.py", line 279, in process_update
    handler.handle_update(update, self)
  File "/Users/irina/Documents/Projects/Lesson3/env/lib/python3.6/site-packages/telegram/ext/commandhandler.py", line 173, in handle_update
    return self.callback(dispatcher.bot, update, **optional_args)
  File "bot.py", line 28, in find_planet
    mars = ephem.Mars(datetime.datetime.now)
NameError: name 'datetime' is not defined
telegram.ext.updater - INFO - Received signal 2 (SIGINT), stopping...
telegram.ext.updater - WARNING - Exiting immediately!
telegram.ext.updater - INFO - Received signal 2 (SIGINT), stopping...
telegram.ext.updater - WARNING - Exiting immediately!
telegram.ext.dispatcher - ERROR - An uncaught error was raised while processing the update
Traceback (most recent call last):
  File "/Users/irina/Documents/Projects/Lesson3/env/lib/python3.6/site-packages/telegram/ext/dispatcher.py", line 279, in process_update
    handler.handle_update(update, self)
  File "/Users/irina/Documents/Projects/Lesson3/env/lib/python3.6/site-packages/telegram/ext/commandhandler.py", line 173, in handle_update
    return self.callback(dispatcher.bot, update, **optional_args)
  File "bot.py", line 28, in find_planet
    mars = ephem.Mars(datetime.datetime.now)
NameError: name 'datetime' is not defined
telegram.ext.updater - INFO - Received signal 2 (SIGINT), stopping...
telegram.ext.updater - WARNING - Exiting immediately!
telegram.ext.dispatcher - ERROR - An uncaught error was raised while processing the update
Traceback (most recent call last):
  File "/Users/irina/Documents/Projects/Lesson3/env/lib/python3.6/site-packages/telegram/ext/dispatcher.py", line 279, in process_update
    handler.handle_update(update, self)
  File "/Users/irina/Documents/Projects/Lesson3/env/lib/python3.6/site-packages/telegram/ext/commandhandler.py", line 173, in handle_update
    return self.callback(dispatcher.bot, update, **optional_args)
  File "bot.py", line 29, in find_planet
    mars = ephem.Mars(datetime.datetime.now)
NameError: name 'datetime' is not defined
telegram.ext.dispatcher - ERROR - An uncaught error was raised while processing the update
Traceback (most recent call last):
  File "/Users/irina/Documents/Projects/Lesson3/env/lib/python3.6/site-packages/telegram/ext/dispatcher.py", line 279, in process_update
    handler.handle_update(update, self)
  File "/Users/irina/Documents/Projects/Lesson3/env/lib/python3.6/site-packages/telegram/ext/commandhandler.py", line 173, in handle_update
    return self.callback(dispatcher.bot, update, **optional_args)
  File "bot.py", line 29, in find_planet
    mars = ephem.Mars(datetime.datetime.now)
NameError: name 'datetime' is not defined
telegram.ext.updater - INFO - Received signal 2 (SIGINT), stopping...
telegram.ext.updater - WARNING - Exiting immediately!
telegram.ext.dispatcher - ERROR - An uncaught error was raised while processing the update
Traceback (most recent call last):
  File "/Users/irina/Documents/Projects/Lesson3/env/lib/python3.6/site-packages/telegram/ext/dispatcher.py", line 279, in process_update
    handler.handle_update(update, self)
  File "/Users/irina/Documents/Projects/Lesson3/env/lib/python3.6/site-packages/telegram/ext/commandhandler.py", line 173, in handle_update
    return self.callback(dispatcher.bot, update, **optional_args)
  File "bot.py", line 27, in find_planet
    mars = ephem.Mars(datetime.datetime.now)
NameError: name 'datetime' is not defined
telegram.ext.dispatcher - ERROR - An uncaught error was raised while processing the update
Traceback (most recent call last):
  File "/Users/irina/Documents/Projects/Lesson3/env/lib/python3.6/site-packages/telegram/ext/dispatcher.py", line 279, in process_update
    handler.handle_update(update, self)
  File "/Users/irina/Documents/Projects/Lesson3/env/lib/python3.6/site-packages/telegram/ext/commandhandler.py", line 173, in handle_update
    return self.callback(dispatcher.bot, update, **optional_args)
  File "bot.py", line 27, in find_planet
    mars = ephem.Mars(datetime.datetime.now)
NameError: name 'datetime' is not defined
telegram.ext.updater - INFO - Received signal 2 (SIGINT), stopping...
telegram.ext.updater - WARNING - Exiting immediately!
telegram.ext.dispatcher - ERROR - An uncaught error was raised while processing the update
Traceback (most recent call last):
  File "/Users/irina/Documents/Projects/Lesson3/env/lib/python3.6/site-packages/telegram/ext/dispatcher.py", line 279, in process_update
    handler.handle_update(update, self)
  File "/Users/irina/Documents/Projects/Lesson3/env/lib/python3.6/site-packages/telegram/ext/commandhandler.py", line 173, in handle_update
    return self.callback(dispatcher.bot, update, **optional_args)
  File "bot.py", line 27, in find_planet
    mars = ephem.Mars(str(datetime.now().today()))
NameError: name 'datetime' is not defined
telegram.ext.updater - INFO - Received signal 2 (SIGINT), stopping...
telegram.ext.updater - WARNING - Exiting immediately!
telegram.ext.dispatcher - ERROR - An uncaught error was raised while processing the update
Traceback (most recent call last):
  File "/Users/irina/Documents/Projects/Lesson3/env/lib/python3.6/site-packages/telegram/ext/dispatcher.py", line 279, in process_update
    handler.handle_update(update, self)
  File "/Users/irina/Documents/Projects/Lesson3/env/lib/python3.6/site-packages/telegram/ext/commandhandler.py", line 173, in handle_update
    return self.callback(dispatcher.bot, update, **optional_args)
  File "bot.py", line 28, in find_planet
    mars = ephem.Mars(str(datetime.now().today()))
NameError: name 'datetime' is not defined
telegram.ext.updater - INFO - Received signal 2 (SIGINT), stopping...
telegram.ext.updater - WARNING - Exiting immediately!
telegram.ext.dispatcher - ERROR - An uncaught error was raised while processing the update
Traceback (most recent call last):
  File "/Users/irina/Documents/Projects/Lesson3/env/lib/python3.6/site-packages/telegram/ext/dispatcher.py", line 279, in process_update
    handler.handle_update(update, self)
  File "/Users/irina/Documents/Projects/Lesson3/env/lib/python3.6/site-packages/telegram/ext/commandhandler.py", line 173, in handle_update
    return self.callback(dispatcher.bot, update, **optional_args)
  File "bot.py", line 28, in find_planet
    mars = ephem.Mars(str(datetime.now().today()))
NameError: name 'datetime' is not defined
telegram.ext.updater - INFO - Received signal 2 (SIGINT), stopping...
telegram.ext.updater - WARNING - Exiting immediately!
telegram.ext.dispatcher - ERROR - An uncaught error was raised while processing the update
Traceback (most recent call last):
  File "/Users/irina/Documents/Projects/Lesson3/env/lib/python3.6/site-packages/telegram/ext/dispatcher.py", line 279, in process_update
    handler.handle_update(update, self)
  File "/Users/irina/Documents/Projects/Lesson3/env/lib/python3.6/site-packages/telegram/ext/commandhandler.py", line 173, in handle_update
    return self.callback(dispatcher.bot, update, **optional_args)
  File "bot.py", line 28, in find_planet
    mars = ephem.Mars(str(datetime.now().today()))
NameError: name 'datetime' is not defined
telegram.ext.updater - INFO - Received signal 2 (SIGINT), stopping...
telegram.ext.updater - WARNING - Exiting immediately!
telegram.ext.dispatcher - ERROR - An uncaught error was raised while processing the update
Traceback (most recent call last):
  File "/Users/irina/Documents/Projects/Lesson3/env/lib/python3.6/site-packages/telegram/ext/dispatcher.py", line 279, in process_update
    handler.handle_update(update, self)
  File "/Users/irina/Documents/Projects/Lesson3/env/lib/python3.6/site-packages/telegram/ext/commandhandler.py", line 173, in handle_update
    return self.callback(dispatcher.bot, update, **optional_args)
  File "bot.py", line 29, in find_planet
    mars = ephem.Mars(str(datetime.now().today()))
NameError: name 'datetime' is not defined
telegram.ext.updater - INFO - Received signal 2 (SIGINT), stopping...
telegram.ext.updater - INFO - Received signal 2 (SIGINT), stopping...
telegram.ext.updater - WARNING - Exiting immediately!
telegram.ext.dispatcher - ERROR - An uncaught error was raised while processing the update
Traceback (most recent call last):
  File "/Users/irina/Documents/Projects/Lesson3/env/lib/python3.6/site-packages/telegram/ext/dispatcher.py", line 279, in process_update
    handler.handle_update(update, self)
  File "/Users/irina/Documents/Projects/Lesson3/env/lib/python3.6/site-packages/telegram/ext/commandhandler.py", line 173, in handle_update
    return self.callback(dispatcher.bot, update, **optional_args)
  File "bot.py", line 33, in find_planet
    update.message.reply_text(ephem.constellation(planet)[1])
ValueError: the sequence specifying a position must have exactly two coordinates
telegram.ext.dispatcher - ERROR - An uncaught error was raised while processing the update
Traceback (most recent call last):
  File "/Users/irina/Documents/Projects/Lesson3/env/lib/python3.6/site-packages/telegram/ext/dispatcher.py", line 279, in process_update
    handler.handle_update(update, self)
  File "/Users/irina/Documents/Projects/Lesson3/env/lib/python3.6/site-packages/telegram/ext/commandhandler.py", line 173, in handle_update
    return self.callback(dispatcher.bot, update, **optional_args)
  File "bot.py", line 33, in find_planet
    update.message.reply_text(ephem.constellation(planet)[1])
ValueError: the sequence specifying a position must have exactly two coordinates
telegram.ext.updater - INFO - Received signal 2 (SIGINT), stopping...
